<?xml version="1.0"?>
<robot name="turtlebot3_waffle_pi" xmlns:xacro="http://ros.org/wiki/xacro">


  <!-- Define properties for common values -->
  <xacro:property name="wheel_radius" value="0.033"/>
  <xacro:property name="wheel_length" value="0.018"/>
  <xacro:property name="base_inertial_mass" value="1.3729096"/>
  <xacro:property name="wheel_inertial_mass" value="0.02849894"/>

  <!-- Define common materials -->
  <xacro:macro name="material" params="name color">
    <material name="${name}">
      <color rgba="${color}"/>
    </material>
  </xacro:macro>

  <xacro:material name="black" color="0.0 0.0 0.0 1.0"/>
  <xacro:material name="dark" color="0.3 0.3 0.3 1.0"/>
  <xacro:material name="light_black" color="0.4 0.4 0.4 1.0"/>
  <xacro:material name="blue" color="0.0 0.0 0.8 1.0"/>
  <xacro:material name="green" color="0.0 0.8 0.0 1.0"/>
  <xacro:material name="grey" color="0.5 0.5 0.5 1.0"/>
  <xacro:material name="orange" color="1.0 0.4235 0.0392 1.0"/>
  <xacro:material name="brown" color="0.8706 0.8118 0.7647 1.0"/>
  <xacro:material name="red" color="0.8 0.0 0.0 1.0"/>
  <xacro:material name="white" color="1.0 1.0 1.0 1.0"/>

  <!-- Base footprint -->
  <link name="base_footprint"/>

  <joint name="base_joint" type="fixed">
    <parent link="base_footprint"/>
    <child link="base_link"/>
    <origin xyz="0 0 0.010" rpy="0 0 0"/>
  </joint>

  <!-- Base link -->
  <link name="base_link">
    <visual>
      <origin xyz="-0.064 0 0.0" rpy="0 0 0"/>
      <geometry>
        <mesh filename="package://om_x_tb3_w_pi/meshes/bases/waffle_pi_base.stl" scale="0.001 0.001 0.001"/>
      </geometry>
      <material name="light_black"/>
    </visual>
    <collision>
      <origin xyz="-0.064 0 0.047" rpy="0 0 0"/>
      <geometry>
        <box size="0.266 0.266 0.094"/>
      </geometry>
    </collision>
    <inertial>
      <origin xyz="0 0 0"/>
      <mass value="${base_inertial_mass}"/>
      <inertia ixx="8.7002718e-03" ixy="-4.7576583e-05" ixz="1.1160499e-04"
               iyy="8.6195418e-03" iyz="-3.5422299e-06"
               izz="1.4612727e-02"/>
    </inertial>
  </link>

  <!-- Wheel joint macro -->
  <xacro:macro name="wheel_joint" params="joint_name link_name xyz">
    <joint name="${joint_name}" type="continuous">
      <parent link="base_link"/>
      <child link="${link_name}"/>
      <origin xyz="${xyz}" rpy="-1.57 0 0"/>
      <axis xyz="0 0 1"/>
    </joint>
  </xacro:macro>

  <!-- Wheel link macro -->
  <xacro:macro name="wheel_link" params="link_name mesh_file">
    <link name="${link_name}">
      <visual>
        <origin xyz="0 0 0" rpy="1.57 0 0"/>
        <geometry>
          <mesh filename="${mesh_file}" scale="0.001 0.001 0.001"/>
        </geometry>
        <material name="dark"/>
      </visual>
      <collision>
        <origin xyz="0 0 0" rpy="0 0 0"/>
        <geometry>
          <cylinder length="${wheel_length}" radius="${wheel_radius}"/>
        </geometry>
      </collision>
      <inertial>
        <origin xyz="0 0 0"/>
        <mass value="${wheel_inertial_mass}"/>
        <inertia ixx="1.1175580e-05" ixy="-4.2369783e-11" ixz="-5.9381719e-09"
                 iyy="1.1192413e-05" iyz="-1.4400107e-11"
                 izz="2.0712558e-05"/>
      </inertial>
    </link>
  </xacro:macro>

  <!-- Wheels -->
  <xacro:wheel_joint joint_name="wheel_left_joint" link_name="wheel_left_link" xyz="0.0 0.144 0.023"/>
  <xacro:wheel_link link_name="wheel_left_link" mesh_file="package://om_x_tb3_w_pi/meshes/wheels/left_tire.stl"/>

  <xacro:wheel_joint joint_name="wheel_right_joint" link_name="wheel_right_link" xyz="0.0 -0.144 0.023"/>
  <xacro:wheel_link link_name="wheel_right_link" mesh_file="package://om_x_tb3_w_pi/meshes/wheels/right_tire.stl"/>

  <!-- Castor wheels -->
  <xacro:macro name="caster_joint" params="joint_name link_name xyz">
    <joint name="${joint_name}" type="fixed">
      <parent link="base_link"/>
      <child link="${link_name}"/>
      <origin xyz="${xyz}" rpy="-1.57 0 0"/>
    </joint>
  </xacro:macro>

  <xacro:macro name="caster_link" params="link_name">
    <link name="${link_name}">
      <collision>
        <origin xyz="0 0.001 0" rpy="0 0 0"/>
        <geometry>
          <box size="0.030 0.009 0.020"/>
        </geometry>
      </collision>
      <inertial>
        <origin xyz="0 0 0"/>
        <mass value="0.005"/>
        <inertia ixx="0.001" ixy="0.0" ixz="0.0"
                 iyy="0.001" iyz="0.0"
                 izz="0.001"/>
      </inertial>
    </link>
  </xacro:macro>

  <xacro:caster_joint joint_name="caster_back_right_joint" link_name="caster_back_right_link" xyz="-0.177 -0.064 -0.004"/>
  <xacro:caster_link link_name="caster_back_right_link"/>

  <xacro:caster_joint joint_name="caster_back_left_joint" link_name="caster_back_left_link" xyz="-0.177 0.064 -0.004"/>
  <xacro:caster_link link_name="caster_back_left_link"/>

  <!-- IMU -->
  <joint name="imu_joint" type="fixed">
    <parent link="base_link"/>
    <child link="imu_link"/>
    <origin xyz="0.0 0 0.068" rpy="0 0 0"/>
  </joint>
  <link name="imu_link"/>

  <!-- Lidar -->
  <joint name="scan_joint" type="fixed">
    <parent link="base_link"/>
    <child link="base_scan"/>
    <origin xyz="-0.064 0 0.122" rpy="0 0 0"/>
  </joint>

  <link name="base_scan">
    <visual>
      <origin xyz="0 0 0.0" rpy="0 0 0"/>
      <geometry>
        <mesh filename="package://om_x_tb3_w_pi/meshes/sensors/lds.stl" scale="0.001 0.001 0.001"/>
      </geometry>
      <material name="dark"/>
    </visual>
    <collision>
      <origin xyz="0.015 0 -0.0065" rpy="0 0 0"/>
      <geometry>
        <cylinder length="0.0315" radius="0.055"/>
      </geometry>
    </collision>
    <inertial>
      <mass value="0.114"/>
      <origin xyz="0 0 0"/>
      <inertia ixx="0.001" ixy="0.0" ixz="0.0"
               iyy="0.001" iyz="0.0"
               izz="0.001"/>
    </inertial>
  </link>

  <!-- Camera -->
  <joint name="camera_joint" type="fixed">
    <origin xyz="0.073 -0.011 0.084" rpy="0 0 0"/>
    <parent link="base_link"/>
    <child link="camera_link"/>
  </joint>

  <link name="camera_link">
    <collision>
      <origin xyz="0.005 0.011 0.013" rpy="0 0 0"/>
      <geometry>
        <box size="0.015 0.030 0.027"/>
      </geometry>
    </collision>
  </link>

  <joint name="camera_rgb_joint" type="fixed">
    <origin xyz="0.003 0.011 0.009" rpy="0 0 0"/>
    <parent link="camera_link"/>
    <child link="camera_rgb_frame"/>
  </joint>
  <link name="camera_rgb_frame"/>

  <joint name="camera_rgb_optical_joint" type="fixed">
    <origin xyz="0 0 0" rpy="-1.57 0 -1.57"/>
    <parent link="camera_rgb_frame"/>
    <child link="camera_rgb_optical_frame"/>
  </joint>
  <link name="camera_rgb_optical_frame"/>

</robot>
