<?xml version="1.0"?>
<robot name="open_manipulator_x">

  <material name="grey">
    <color rgba="0.5 0.5 0.5 1.0"/>
  </material>

  <material name="red">
    <color rgba="0.8 0.0 0.0 1.0"/>
  </material>
  
  <!-- Base link -->
  <link name="base_manipulator">

  </link>

  <!-- Joint to connect base_manipulator to link1 -->
  <joint name="base_to_link1_joint" type="fixed">
    <parent link="base_manipulator"/>
    <child link="link1"/>
    <origin xyz="0 0 0.05" rpy="0 0 0"/>
  </joint>

  <!-- Existing links and joints -->

  <link name="link1">
    <visual>
      <origin xyz="0 0 0" rpy="0 0 0"/>
      <geometry>
        <mesh filename="package://om_x_tb3_w_pi/meshes/link1.stl" scale="0.001 0.001 0.001"/>
      </geometry>
      <material name="grey"/>
    </visual>
    <collision>
      <origin xyz="0 0 0" rpy="0 0 0"/>
      <geometry>
        <mesh filename="package://om_x_tb3_w_pi/meshes/link1.stl" scale="0.001 0.001 0.001"/>
      </geometry>
    </collision>
    <inertial>
      <origin xyz="0.00030876154 0 -0.00012176461" />
      <mass value="0.079119962"/>
      <inertia ixx="1.2505234e-05" ixy="0.0" ixz="-1.7855208e-07" 
               iyy="2.1898364e-05" iyz="0.0" izz="1.9267361e-05" />
    </inertial>
  </link>


  <joint name="joint1" type="revolute">
    <parent link="link1"/>
    <child link="link2"/>
    <origin xyz="0.012 0.0 0.017" rpy="0 0 0"/>
    <axis xyz="0 0 1"/>
    <limit velocity="4.8" effort="1" lower="-3.14159" upper="3.14159"/>
    <dynamics damping="0.1"/>
  </joint>

  <link name="link2">
    <visual>
      <origin xyz="0 0 0.019" rpy="0 0 0"/>
      <geometry>
        <mesh filename="package://om_x_tb3_w_pi/meshes/link2.stl" scale="0.001 0.001 0.001"/>
      </geometry>
      <material name="grey"/>
    </visual>
    <collision>
      <origin xyz="0 0 0.019" rpy="0 0 0"/>
      <geometry>
        <mesh filename="package://om_x_tb3_w_pi/meshes/link2.stl" scale="0.001 0.001 0.001"/>
      </geometry>
    </collision>
    <inertial>
      <origin xyz="-0.0003018487 0.00054043684 0.047433464"/>
      <mass value="0.098406837"/>
      <inertia ixx="3.4543422e-05" ixy="-1.6031095e-08" ixz="-3.8375155e-07" 
               iyy="3.2689329e-05" iyz="2.8511935e-08" izz="1.8850320e-05" />
    </inertial>
  </link>

  <joint name="joint2" type="revolute">
    <parent link="link2"/>
    <child link="link3"/>
    <origin xyz="0.0 0.0 0.0595" rpy="0 0 0"/>
    <axis xyz="0 1 0"/>
    <limit velocity="4.8" effort="1" lower="-1.5" upper="1.5"/>
    <dynamics damping="0.1"/>
  </joint>

  <link name="link3">
    <visual>
      <origin xyz="0 0 0" rpy="0 0 0"/>
      <geometry>
        <mesh filename="package://om_x_tb3_w_pi/meshes/link3.stl" scale="0.001 0.001 0.001"/>
      </geometry>
      <material name="grey"/>
    </visual>
    <collision>
      <origin xyz="0 0 0" rpy="0 0 0"/>
      <geometry>
        <mesh filename="package://om_x_tb3_w_pi/meshes/link3.stl" scale="0.001 0.001 0.001"/>
      </geometry>
    </collision>
    <inertial>
      <origin xyz="0.010308393 0.00037743363 0.10170197"/>
      <mass value="0.13850917"/>
      <inertia ixx="0.00033055381" ixy="-9.7940978e-08" ixz="-3.8505711e-05" 
               iyy="0.00034290447" iyz="-1.5717516e-06" izz="6.0346498e-05" />
    </inertial>
  </link>

  <joint name="joint3" type="revolute">
    <parent link="link3"/>
    <child link="link4"/>
    <origin xyz="0.024 0 0.128" rpy="0 0 0"/>
    <axis xyz="0 1 0"/>
    <limit velocity="4.8" effort="1" lower="-1.5" upper="1.4"/>
    <dynamics damping="0.1"/>
  </joint>

  <link name="link4">
    <visual>
      <origin xyz="0 0 0" rpy="0 0 0"/>
      <geometry>
        <mesh filename="package://om_x_tb3_w_pi/meshes/link4.stl" scale="0.001 0.001 0.001"/>
      </geometry>
      <material name="grey"/>
    </visual>
    <collision>
      <origin xyz="0 0 0" rpy="0 0 0"/>
      <geometry>
        <mesh filename="package://om_x_tb3_w_pi/meshes/link4.stl" scale="0.001 0.001 0.001"/>
      </geometry>
    </collision>
    <inertial>
      <origin xyz="0.09090959 0.00038929816 0.00022413279"/>
      <mass value="0.13274562"/>
      <inertia ixx="3.0654178e-05" ixy="-1.2764155e-06" ixz="-2.6874417e-07" 
               iyy="2.4230292e-04" iyz="1.1559550e-08" izz="2.5155057e-04" />
    </inertial>
  </link>

  <joint name="joint4" type="revolute">
    <parent link="link4"/>
    <child link="link5"/>
    <origin xyz="0.124 0.0 0.0" rpy="0 0 0"/>
    <axis xyz="0 1 0"/>
    <limit velocity="4.8" effort="1" lower="-1.7" upper="1.97"/>
    <dynamics damping="0.1"/>
  </joint>

  <link name="link5">
    <visual>
      <origin xyz="0 0 0" rpy="0 0 0"/>
      <geometry>
        <mesh filename="package://om_x_tb3_w_pi/meshes/link5.stl" scale="0.001 0.001 0.001"/>
      </geometry>
      <material name="grey"/>
    </visual>
    <collision>
      <origin xyz="0 0 0" rpy="0 0 0"/>
      <geometry>
        <mesh filename="package://om_x_tb3_w_pi/meshes/link5.stl" scale="0.001 0.001 0.001"/>
      </geometry>
    </collision>
    <inertial>
      <origin xyz="0.044206755 3.6839985e-07 0.0089142216"/>
      <mass value="0.14327573"/>
      <inertia ixx="8.0870749e-05" ixy="0.0" ixz="-1.0157896e-06" 
               iyy="7.5980465e-05" iyz="0.0" izz="9.3127351e-05" />
    </inertial>
  </link>

  <joint name="gripper_left_joint" type="prismatic">
    <parent link="link5"/>
    <child link="gripper_left_link"/>
    <origin xyz="0.0817 0.021 0.0" rpy="0 0 0"/>
    <axis xyz="0 1 0"/>
    <limit velocity="4.8" effort="1" lower="-0.010" upper="0.019"/>
    <dynamics damping="0.1"/>
  </joint>

  <link name="gripper_left_link">
    <visual>
      <origin xyz="0 0 0" rpy="0 0 0"/>
      <geometry>
        <mesh filename="package://om_x_tb3_w_pi/meshes/gripper_left_palm.stl" scale="0.001 0.001 0.001"/>
      </geometry>
      <material name="grey"/>
    </visual>
    <collision>
      <origin xyz="0 0 0" rpy="0 0 0"/>
      <geometry>
        <mesh filename="package://om_x_tb3_w_pi/meshes/gripper_left_palm.stl" scale="0.001 0.001 0.001"/>
      </geometry>
    </collision>
    <inertial>
      <origin xyz="0 0 0"/>
      <mass value="0.001"/>
      <inertia ixx="1.0e-06" ixy="0.0" ixz="0.0" 
               iyy="1.0e-06" iyz="0.0" izz="1.0e-06" />
    </inertial>
  </link>

  <joint name="gripper_right_joint" type="prismatic">
    <parent link="link5"/>
    <child link="gripper_right_link"/>
    <origin xyz="0.0817 -0.021 0" rpy="0 0 0"/>
    <axis xyz="0 -1 0"/>
    <limit velocity="4.8" effort="1" lower="-0.010" upper="0.019"/>
    <mimic joint="gripper_left_joint" multiplier="1"/>
    <dynamics damping="0.1"/>
  </joint>

  <link name="gripper_right_link">
    <visual>
      <origin xyz="0 0 0" rpy="0 0 0"/>
      <geometry>
        <mesh filename="package://om_x_tb3_w_pi/meshes/gripper_right_palm.stl" scale="0.001 0.001 0.001"/>
      </geometry>
      <material name="grey"/>
    </visual>
    <collision>
      <origin xyz="0 0 0" rpy="0 0 0"/>
      <geometry>
        <mesh filename="package://om_x_tb3_w_pi/meshes/gripper_right_palm.stl" scale="0.001 0.001 0.001"/>
      </geometry>
    </collision>
    <inertial>
      <origin xyz="0 0 0"/>
      <mass value="0.001"/>
      <inertia ixx="1.0e-06" ixy="0.0" ixz="0.0" 
               iyy="1.0e-06" iyz="0.0" izz="1.0e-06" />
    </inertial>
  </link>

  <joint name="end_effector_joint" type="fixed">
    <parent link="link5"/>
    <child link="end_effector_link"/>
    <origin xyz="0.126 0.0 0.0" rpy="0 0 0"/>
  </joint>

  <link name="end_effector_link">
    <visual>
      <origin xyz="0 0 0" rpy="0 0 0"/>
      <geometry>
        <box size="0.01 0.01 0.01"/>
      </geometry>
      <material name="red"/>
    </visual>
  </link>

</robot>
