<?xml version="1.0" encoding="utf-8"?>
<!-- This URDF was automatically created by SolidWorks to URDF Exporter! Originally created by
Stephen Brawner (brawner@gmail.com) 
     Commit Version: 1.6.0-4-g7f85cfe  Build Version: 1.6.7995.38578
     For more information, please see http://wiki.ros.org/sw_urdf_exporter -->
<robot name="go2_description" xmlns:xacro="http://ros.org/wiki/xacro">
    <xacro:arg name="namespace" default="" />

    <link name="base_link"></link>
    
    <joint name="base_joint_link" type="fixed">
        <parent link="base_link"/>
        <child link="base" />
        <origin xyz="0 0 0.5" rpy="0 0 0"/>
    </joint>

  <link
    name="base">
    <inertial>
      <origin
        xyz="0.021112 0 -0.005366"
        rpy="0 0 0" />
      <mass
        value="6.921" />
      <inertia
        ixx="0.02448"
        ixy="0.00012166"
        ixz="0.0014849"
        iyy="0.098077"
        iyz="-3.12E-05"
        izz="0.107" />
    </inertial>
    <visual>
      <origin
        xyz="0 0 0"
        rpy="0 0 0" />
      <geometry>
        <mesh
          filename="package://go2_description/dae/base.dae" />
      </geometry>
      <material
        name="">
        <color
          rgba="1 1 1 1" />
      </material>
    </visual>
    <collision>
      <origin rpy="0 0 0" xyz="0 0 0" />
      <geometry>
        <box size="0.3762 0.0935 0.114" />
      </geometry>
    </collision>
  </link>
  <link
    name="Head_upper">
    <inertial>
      <origin
        xyz="0 0 0"
        rpy="0 0 0" />
      <mass
        value="0.001" />
      <inertia
        ixx="9.6e-06"
        ixy="0"
        ixz="0"
        iyy="9.6e-06"
        iyz="0"
        izz="9.6e-06" />
    </inertial>
    <collision>
      <origin
        xyz="0 0 0"
        rpy="0 0 0" />
      <geometry>
        <cylinder radius="0.05" length="0.09" />
      </geometry>
    </collision>
  </link>
  <joint
    name="Head_upper_joint"
    type="fixed" dont_collapse="true">
    <origin
      xyz="0.285 0 0.01"
      rpy="0 0 0" />
    <parent
      link="base" />
    <child
      link="Head_upper" />
    <axis
      xyz="0 0 0" />
  </joint>
  <link
    name="Head_lower">
    <inertial>
      <origin
        xyz="0 0 0"
        rpy="0 0 0" />
      <mass
        value="0.001" />
      <inertia
        ixx="9.6e-06"
        ixy="0"
        ixz="0"
        iyy="9.6e-06"
        iyz="0"
        izz="9.6e-06" />
    </inertial>
    <collision>
      <origin
        xyz="0 0 0"
        rpy="0 0 0" />
      <geometry>
        <sphere radius="0.047" />
      </geometry>
    </collision>
  </link>
  <joint
    name="Head_lower_joint"
    type="fixed" dont_collapse="true">
    <origin
      xyz="0.008 0 -0.07"
      rpy="0 0 0" />
    <parent
      link="Head_upper" />
    <child
      link="Head_lower" />
    <axis
      xyz="0 0 0" />
  </joint>
  <link
    name="FL_hip">
    <inertial>
      <origin
        xyz="-0.0054 0.00194 -0.000105"
        rpy="0 0 0" />
      <mass
        value="0.678" />
      <inertia
        ixx="0.00048"
        ixy="-3.01E-06"
        ixz="1.11E-06"
        iyy="0.000884"
        iyz="-1.42E-06"
        izz="0.000596" />
    </inertial>
    <visual>
      <origin
        xyz="0 0 0"
        rpy="0 0 0" />
      <geometry>
        <mesh
          filename="package://go2_description/dae/hip.dae" />
      </geometry>
      <material
        name="">
        <color
          rgba="1 1 1 1" />
      </material>
    </visual>
    <collision>
      <origin rpy="1.5707963267948966 0 0" xyz="0 0.08 0" />
      <geometry>
        <cylinder length="0.04" radius="0.046" />
      </geometry>
    </collision>
  </link>
  <joint
    name="FL_hip_joint"
    type="revolute">
    <origin
      xyz="0.1934 0.0465 0"
      rpy="0 0 0" />
    <parent
      link="base" />
    <child
      link="FL_hip" />
    <axis
      xyz="1 0 0" />
    <limit
      lower="-1.0472"
      upper="1.0472"
      effort="23.7"
      velocity="30.1" />
  </joint>
  <link name="FL_hip_rotor">
    <inertial>
      <origin rpy="0 0 0" xyz="0.0 0.0 0.0"/>
      <mass value="0.089"/>
      <inertia ixx="0.000111842" ixy="0.0" ixz="0.0" iyy="0.000059647" iyz="0.0" izz="0.000059647"/>
    </inertial>
  </link>
  <joint name="FL_hip_rotor_joint" type="fixed">
    <origin rpy="0 0 0" xyz="0.11215 0.04675 0"/>
    <parent link="base"/>
    <child link="FL_hip_rotor"/>
  </joint>
  <link
    name="FL_thigh">
    <inertial>
      <origin
        xyz="-0.00374 -0.0223 -0.0327"
        rpy="0 0 0" />
      <mass
        value="1.152" />
      <inertia
        ixx="0.00584"
        ixy="8.72E-05"
        ixz="-0.000289"
        iyy="0.0058"
        iyz="0.000808"
        izz="0.00103" />
    </inertial>
    <visual>
      <origin
        xyz="0 0 0"
        rpy="0 0 0" />
      <geometry>
        <mesh
          filename="package://go2_description/dae/thigh.dae" />
      </geometry>
      <material
        name="">
        <color
          rgba="1 1 1 1" />
      </material>
    </visual>
    <collision>
      <origin rpy="0 1.5707963267948966 0" xyz="0 0 -0.1065" />
      <geometry>
        <box size="0.213 0.0245 0.034" />
      </geometry>
    </collision>
  </link>
  <joint
    name="FL_thigh_joint"
    type="revolute">
    <origin
      xyz="0 0.0955 0"
      rpy="0 0 0" />
    <parent
      link="FL_hip" />
    <child
      link="FL_thigh" />
    <axis
      xyz="0 1 0" />
    <limit
      lower="-1.5708"
      upper="3.4907"
      effort="23.7"
      velocity="30.1" />
  </joint>
  <link name="FL_thigh_rotor">
    <inertial>
      <origin rpy="0 0 0" xyz="0.0 0.0 0.0"/>
      <mass value="0.089"/>
      <inertia ixx="0.000059647" ixy="0.0" ixz="0.0" iyy="0.000111842" iyz="0.0" izz="0.000059647"/>
    </inertial>
  </link>
  <joint name="FL_thigh_rotor_joint" type="fixed">
    <origin rpy="0 0 0" xyz="0 -0.00015 0"/>
    <parent link="FL_hip"/>
    <child link="FL_thigh_rotor"/>
  </joint>
  <link
    name="FL_calf">
    <inertial>
      <origin
        xyz="0.00548 -0.000975 -0.115"
        rpy="0 0 0" />
      <mass
        value="0.154" />
      <inertia
        ixx="0.00108"
        ixy="3.4E-07"
        ixz="1.72E-05"
        iyy="0.0011"
        iyz="8.28E-06"
        izz="3.29E-05" />
    </inertial>
    <visual>
      <origin
        xyz="0 0 0"
        rpy="0 0 0" />
      <geometry>
        <mesh
          filename="package://go2_description/dae/calf.dae" />
      </geometry>
      <material
        name="">
        <color
          rgba="1 1 1 1" />
      </material>
    </visual>
    <collision>
      <origin rpy="0 -0.21 0" xyz="0.008 0 -0.06" />
      <geometry>
        <cylinder length="0.12" radius="0.012" />
      </geometry>
    </collision>
  </link>
  <joint
    name="FL_calf_joint"
    type="revolute">
    <origin
      xyz="0 0 -0.213"
      rpy="0 0 0" />
    <parent
      link="FL_thigh" />
    <child
      link="FL_calf" />
    <axis
      xyz="0 1 0" />
    <limit
      lower="-2.7227"
      upper="-0.83776"
      effort="45.43"
      velocity="15.70" />
  </joint>
  <link
    name="FL_calflower">
    <collision>
      <origin rpy="0 0 0" xyz="0 0 0" />
      <geometry>
        <cylinder length="0.065" radius="0.011" />
      </geometry>
    </collision>
  </link>
  <joint
    name="FL_calflower_joint"
    type="fixed">
    <origin
      xyz="0.020 0 -0.148"
      rpy="0 0.05 0" />
    <parent
      link="FL_calf" />
    <child
      link="FL_calflower" />
    <axis
      xyz="0 0 0" />
  </joint>
  <link
    name="FL_calflower1">
    <collision>
      <origin rpy="0 0 0" xyz="0 0 0" />
      <geometry>
        <cylinder length="0.03" radius="0.0155" />
      </geometry>
    </collision>
  </link>
  <joint
    name="FL_calflower1_joint"
    type="fixed">
    <origin
      xyz="-0.01 0 -0.04"
      rpy="0 0.48 0" />
    <parent
      link="FL_calflower" />
    <child
      link="FL_calflower1" />
    <axis
      xyz="0 0 0" />
  </joint>
  <link name="FL_calf_rotor">
    <inertial>
      <origin rpy="0 0 0" xyz="0.0 0.0 0.0"/>
      <mass value="0.089"/>
      <inertia ixx="0.000059647" ixy="0.0" ixz="0.0" iyy="0.000111842" iyz="0.0" izz="0.000059647"/>
    </inertial>
  </link>
  <joint name="FL_calf_rotor_joint" type="fixed">
    <origin rpy="0 0 0" xyz="0 -0.03235 0"/>
    <parent link="FL_thigh"/>
    <child link="FL_calf_rotor"/>
  </joint>
  <link
    name="FL_foot">
    <inertial>
      <origin
        xyz="0 0 0"
        rpy="0 0 0" />
      <mass
        value="0.04" />
      <inertia
        ixx="9.6e-06"
        ixy="0"
        ixz="0"
        iyy="9.6e-06"
        iyz="0"
        izz="9.6e-06" />
    </inertial>
    <visual>
      <origin
        xyz="0 0 0"
        rpy="0 0 0" />
      <geometry>
        <mesh
          filename="package://go2_description/dae/foot.dae" />
      </geometry>
      <material
        name="">
        <color
          rgba="1 1 1 1" />
      </material>
    </visual>
    <collision>
      <origin rpy="0 0 0" xyz="-0.002 0 0" />
      <geometry>
        <sphere radius="0.022" />
      </geometry>
    </collision>
  </link>
  <joint
    name="FL_foot_joint"
    type="fixed" dont_collapse="true">
    <origin
      xyz="0 0 -0.213"
      rpy="0 0 0" />
    <parent
      link="FL_calf" />
    <child
      link="FL_foot" />
    <axis
      xyz="0 0 0" />
  </joint>
  <link
    name="FR_hip">
    <inertial>
      <origin
        xyz="-0.0054 -0.00194 -0.000105"
        rpy="0 0 0" />
      <mass
        value="0.678" />
      <inertia
        ixx="0.00048"
        ixy="3.01E-06"
        ixz="1.11E-06"
        iyy="0.000884"
        iyz="1.42E-06"
        izz="0.000596" />
    </inertial>
    <visual>
      <origin
        xyz="0 0 0"
        rpy="3.1415 0 0" />
      <geometry>
        <mesh
          filename="package://go2_description/dae/hip.dae" />
      </geometry>
      <material
        name="">
        <color
          rgba="1 1 1 1" />
      </material>
    </visual>
    <collision>
      <origin rpy="1.5707963267948966 0 0" xyz="0 -0.08 0" />
      <geometry>
        <cylinder length="0.04" radius="0.046" />
      </geometry>
    </collision>
  </link>
  <joint
    name="FR_hip_joint"
    type="revolute">
    <origin
      xyz="0.1934 -0.0465 0"
      rpy="0 0 0" />
    <parent
      link="base" />
    <child
      link="FR_hip" />
    <axis
      xyz="1 0 0" />
    <limit
      lower="-1.0472"
      upper="1.0472"
      effort="23.7"
      velocity="30.1" />
  </joint>
  <link name="FR_hip_rotor">
    <inertial>
      <origin rpy="0 0 0" xyz="0.0 0.0 0.0"/>
      <mass value="0.089"/>
      <inertia ixx="0.000111842" ixy="0.0" ixz="0.0" iyy="0.000059647" iyz="0.0" izz="0.000059647"/>
    </inertial>
  </link>
  <joint name="FR_hip_rotor_joint" type="fixed">
    <origin rpy="0 0 0" xyz="0.11215 -0.04675 0"/>
    <parent link="base"/>
    <child link="FR_hip_rotor"/>
  </joint>
  <link
    name="FR_thigh">
    <inertial>
      <origin
        xyz="-0.00374 0.0223 -0.0327"
        rpy="0 0 0" />
      <mass
        value="1.152" />
      <inertia
        ixx="0.00584"
        ixy="-8.72E-05"
        ixz="-0.000289"
        iyy="0.0058"
        iyz="-0.000808"
        izz="0.00103" />
    </inertial>
    <visual>
      <origin
        xyz="0 0 0"
        rpy="0 0 0" />
      <geometry>
        <mesh
          filename="package://go2_description/dae/thigh_mirror.dae" />
      </geometry>
      <material
        name="">
        <color
          rgba="1 1 1 1" />
      </material>
    </visual>
    <collision>
      <origin rpy="0 1.5707963267948966 0" xyz="0 0 -0.1065" />
      <geometry>
        <box size="0.213 0.0245 0.034" />
      </geometry>
    </collision>
  </link>
  <joint
    name="FR_thigh_joint"
    type="revolute">
    <origin
      xyz="0 -0.0955 0"
      rpy="0 0 0" />
    <parent
      link="FR_hip" />
    <child
      link="FR_thigh" />
    <axis
      xyz="0 1 0" />
    <limit
      lower="-1.5708"
      upper="3.4907"
      effort="23.7"
      velocity="30.1" />
  </joint>
  <link name="FR_thigh_rotor">
    <inertial>
      <origin rpy="0 0 0" xyz="0.0 0.0 0.0"/>
      <mass value="0.089"/>
      <inertia ixx="0.000059647" ixy="0.0" ixz="0.0" iyy="0.000111842" iyz="0.0" izz="0.000059647"/>
    </inertial>
  </link>
  <joint name="FR_thigh_rotor_joint" type="fixed">
    <origin rpy="0 0 0" xyz="0 0.00015 0"/>
    <parent link="FR_hip"/>
    <child link="FR_thigh_rotor"/>
  </joint>
  <link
    name="FR_calf">
    <inertial>
      <origin
        xyz="0.00548 0.000975 -0.115"
        rpy="0 0 0" />
      <mass
        value="0.154" />
      <inertia
        ixx="0.00108"
        ixy="-3.4E-07"
        ixz="1.72E-05"
        iyy="0.0011"
        iyz="-8.28E-06"
        izz="3.29E-05" />
    </inertial>
    <visual>
      <origin
        xyz="0 0 0"
        rpy="0 0 0" />
      <geometry>
        <mesh
          filename="package://go2_description/dae/calf_mirror.dae" />
      </geometry>
      <material
        name="">
        <color
          rgba="1 1 1 1" />
      </material>
    </visual>
    <collision>
      <origin rpy="0 -0.2 0" xyz="0.01 0 -0.06" />
      <geometry>
        <cylinder length="0.12" radius="0.013" />
      </geometry>
    </collision>
  </link>
  <joint
    name="FR_calf_joint"
    type="revolute">
    <origin
      xyz="0 0 -0.213"
      rpy="0 0 0" />
    <parent
      link="FR_thigh" />
    <child
      link="FR_calf" />
    <axis
      xyz="0 1 0" />
    <limit
      lower="-2.7227"
      upper="-0.83776"
      effort="45.43"
      velocity="15.70" />
  </joint>
  <link
    name="FR_calflower">
    <collision>
      <origin rpy="0 0 0" xyz="0 0 0" />
      <geometry>
        <cylinder length="0.065" radius="0.011" />
      </geometry>
    </collision>
  </link>
  <joint
    name="FR_calflower_joint"
    type="fixed">
    <origin
      xyz="0.020 0 -0.148"
      rpy="0 0.05 0" />
    <parent
      link="FR_calf" />
    <child
      link="FR_calflower" />
    <axis
      xyz="0 0 0" />
  </joint>
  <link
    name="FR_calflower1">
    <collision>
      <origin rpy="0 0 0" xyz="0 0 0" />
      <geometry>
        <cylinder length="0.03" radius="0.0155" />
      </geometry>
    </collision>
  </link>
  <joint
    name="FR_calflower1_joint"
    type="fixed">
    <origin
      xyz="-0.01 0 -0.04"
      rpy="0 0.48 0" />
    <parent
      link="FR_calflower" />
    <child
      link="FR_calflower1" />
    <axis
      xyz="0 0 0" />
  </joint>
  <link name="FR_calf_rotor">
    <inertial>
      <origin rpy="0 0 0" xyz="0.0 0.0 0.0"/>
      <mass value="0.089"/>
      <inertia ixx="0.000059647" ixy="0.0" ixz="0.0" iyy="0.000111842" iyz="0.0" izz="0.000059647"/>
    </inertial>
  </link>
  <joint name="FR_calf_rotor_joint" type="fixed">
    <origin rpy="0 0 0" xyz="0 0.03235 0"/>
    <parent link="FR_thigh"/>
    <child link="FR_calf_rotor"/>
  </joint>
  <link
    name="FR_foot">
    <inertial>
      <origin
        xyz="0 0 0"
        rpy="0 0 0" />
      <mass
        value="0.04" />
      <inertia
        ixx="9.6e-06"
        ixy="0"
        ixz="0"
        iyy="9.6e-06"
        iyz="0"
        izz="9.6e-06" />
    </inertial>
    <visual>
      <origin
        xyz="0 0 0"
        rpy="0 0 0" />
      <geometry>
        <mesh
          filename="package://go2_description/dae/foot.dae" />
      </geometry>
      <material
        name="">
        <color
          rgba="1 1 1 1" />
      </material>
    </visual>
    <collision>
      <origin rpy="0 0 0" xyz="-0.002 0 0" />
      <geometry>
        <sphere radius="0.022" />
      </geometry>
    </collision>
  </link>
  <joint
    name="FR_foot_joint"
    type="fixed" dont_collapse="true">
    <origin
      xyz="0 0 -0.213"
      rpy="0 0 0" />
    <parent
      link="FR_calf" />
    <child
      link="FR_foot" />
    <axis
      xyz="0 0 0" />
  </joint>
  <link
    name="RL_hip">
    <inertial>
      <origin
        xyz="0.0054 0.00194 -0.000105"
        rpy="0 0 0" />
      <mass
        value="0.678" />
      <inertia
        ixx="0.00048"
        ixy="3.01E-06"
        ixz="-1.11E-06"
        iyy="0.000884"
        iyz="-1.42E-06"
        izz="0.000596" />
    </inertial>
    <visual>
      <origin
        xyz="0 0 0"
        rpy="0 3.1415 0" />
      <geometry>
        <mesh
          filename="package://go2_description/dae/hip.dae" />
      </geometry>
      <material
        name="">
        <color
          rgba="1 1 1 1" />
      </material>
    </visual>
    <collision>
      <origin rpy="1.5707963267948966 0 0" xyz="0 0.08 0" />
      <geometry>
        <cylinder length="0.04" radius="0.046" />
      </geometry>
    </collision>
  </link>
  <joint
    name="RL_hip_joint"
    type="revolute">
    <origin
      xyz="-0.1934 0.0465 0"
      rpy="0 0 0" />
    <parent
      link="base" />
    <child
      link="RL_hip" />
    <axis
      xyz="1 0 0" />
    <limit
      lower="-1.0472"
      upper="1.0472"
      effort="23.7"
      velocity="30.1" />
  </joint>
  <link name="RL_hip_rotor">
    <inertial>
      <origin rpy="0 0 0" xyz="0.0 0.0 0.0"/>
      <mass value="0.089"/>
      <inertia ixx="0.000111842" ixy="0.0" ixz="0.0" iyy="0.000059647" iyz="0.0" izz="0.000059647"/>
    </inertial>
  </link>
  <joint name="RL_hip_rotor_joint" type="fixed">
    <origin rpy="0 0 0" xyz="-0.11215 0.04675 0"/>
    <parent link="base"/>
    <child link="RL_hip_rotor"/>
  </joint>
  <link
    name="RL_thigh">
    <inertial>
      <origin
        xyz="-0.00374 -0.0223 -0.0327"
        rpy="0 0 0" />
      <mass
        value="1.152" />
      <inertia
        ixx="0.00584"
        ixy="8.72E-05"
        ixz="-0.000289"
        iyy="0.0058"
        iyz="0.000808"
        izz="0.00103" />
    </inertial>
    <visual>
      <origin
        xyz="0 0 0"
        rpy="0 0 0" />
      <geometry>
        <mesh
          filename="package://go2_description/dae/thigh.dae" />
      </geometry>
      <material
        name="">
        <color
          rgba="1 1 1 1" />
      </material>
    </visual>
    <collision>
      <origin rpy="0 1.5707963267948966 0" xyz="0 0 -0.1065" />
      <geometry>
        <box size="0.213 0.0245 0.034" />
      </geometry>
    </collision>
  </link>
  <joint
    name="RL_thigh_joint"
    type="revolute">
    <origin
      xyz="0 0.0955 0"
      rpy="0 0 0" />
    <parent
      link="RL_hip" />
    <child
      link="RL_thigh" />
    <axis
      xyz="0 1 0" />
    <limit
      lower="-0.5236"
      upper="4.5379"
      effort="23.7"
      velocity="30.1" />
  </joint>
  <link name="RL_thigh_rotor">
    <inertial>
      <origin rpy="0 0 0" xyz="0.0 0.0 0.0"/>
      <mass value="0.089"/>
      <inertia ixx="0.000059647" ixy="0.0" ixz="0.0" iyy="0.000111842" iyz="0.0" izz="0.000059647"/>
    </inertial>
  </link>
  <joint name="RL_thigh_rotor_joint" type="fixed">
    <origin rpy="0 0 0" xyz="0 -0.00015 0"/>
    <parent link="RL_hip"/>
    <child link="RL_thigh_rotor"/>
  </joint>
  <link
    name="RL_calf">
    <inertial>
      <origin
        xyz="0.00548 -0.000975 -0.115"
        rpy="0 0 0" />
      <mass
        value="0.154" />
      <inertia
        ixx="0.00108"
        ixy="3.4E-07"
        ixz="1.72E-05"
        iyy="0.0011"
        iyz="8.28E-06"
        izz="3.29E-05" />
    </inertial>
    <visual>
      <origin
        xyz="0 0 0"
        rpy="0 0 0" />
      <geometry>
        <mesh
          filename="package://go2_description/dae/calf.dae" />
      </geometry>
      <material
        name="">
        <color
          rgba="1 1 1 1" />
      </material>
    </visual>
    <collision>
      <origin rpy="0 -0.2 0" xyz="0.01 0 -0.06" />
      <geometry>
        <cylinder length="0.12" radius="0.013" />
      </geometry>
    </collision>
  </link>
  <joint
    name="RL_calf_joint"
    type="revolute">
    <origin
      xyz="0 0 -0.213"
      rpy="0 0 0" />
    <parent
      link="RL_thigh" />
    <child
      link="RL_calf" />
    <axis
      xyz="0 1 0" />
    <limit
      lower="-2.7227"
      upper="-0.83776"
      effort="45.43"
      velocity="15.70" />
  </joint>
  <link
    name="RL_calflower">
    <collision>
      <origin rpy="0 0 0" xyz="0 0 0" />
      <geometry>
        <cylinder length="0.065" radius="0.011" />
      </geometry>
    </collision>
  </link>
  <joint
    name="RL_calflower_joint"
    type="fixed">
    <origin
      xyz="0.020 0 -0.148"
      rpy="0 0.05 0" />
    <parent
      link="RL_calf" />
    <child
      link="RL_calflower" />
    <axis
      xyz="0 0 0" />
  </joint>
  <link
    name="RL_calflower1">
    <collision>
      <origin rpy="0 0 0" xyz="0 0 0" />
      <geometry>
        <cylinder length="0.03" radius="0.0155" />
      </geometry>
    </collision>
  </link>
  <joint
    name="RL_calflower1_joint"
    type="fixed">
    <origin
      xyz="-0.01 0 -0.04"
      rpy="0 0.48 0" />
    <parent
      link="RL_calflower" />
    <child
      link="RL_calflower1" />
    <axis
      xyz="0 0 0" />
  </joint>
  <link name="RL_calf_rotor">
    <inertial>
      <origin rpy="0 0 0" xyz="0.0 0.0 0.0"/>
      <mass value="0.089"/>
      <inertia ixx="0.000059647" ixy="0.0" ixz="0.0" iyy="0.000111842" iyz="0.0" izz="0.000059647"/>
    </inertial>
  </link>
  <joint name="RL_calf_rotor_joint" type="fixed">
    <origin rpy="0 0 0" xyz="0 -0.03235 0"/>
    <parent link="RL_thigh"/>
    <child link="RL_calf_rotor"/>
  </joint>
  <link
    name="RL_foot">
    <inertial>
      <origin
        xyz="0 0 0"
        rpy="0 0 0" />
      <mass
        value="0.04" />
      <inertia
        ixx="9.6e-06"
        ixy="0"
        ixz="0"
        iyy="9.6e-06"
        iyz="0"
        izz="9.6e-06" />
    </inertial>
    <visual>
      <origin
        xyz="0 0 0"
        rpy="0 0 0" />
      <geometry>
        <mesh
          filename="package://go2_description/dae/foot.dae" />
      </geometry>
      <material
        name="">
        <color
          rgba="1 1 1 1" />
      </material>
    </visual>
    <collision>
      <origin rpy="0 0 0" xyz="-0.002 0 0" />
      <geometry>
        <sphere radius="0.022" />
      </geometry>
    </collision>
  </link>
  <joint
    name="RL_foot_joint"
    type="fixed" dont_collapse="true">
    <origin
      xyz="0 0 -0.213"
      rpy="0 0 0" />
    <parent
      link="RL_calf" />
    <child
      link="RL_foot" />
    <axis
      xyz="0 0 0" />
  </joint>
  <link
    name="RR_hip">
    <inertial>
      <origin
        xyz="0.0054 -0.00194 -0.000105"
        rpy="0 0 0" />
      <mass
        value="0.678" />
      <inertia
        ixx="0.00048"
        ixy="-3.01E-06"
        ixz="-1.11E-06"
        iyy="0.000884"
        iyz="1.42E-06"
        izz="0.000596" />
    </inertial>
    <visual>
      <origin
        xyz="0 0 0"
        rpy="3.1415 3.1415 0" />
      <geometry>
        <mesh
          filename="package://go2_description/dae/hip.dae" />
      </geometry>
      <material
        name="">
        <color
          rgba="1 1 1 1" />
      </material>
    </visual>
    <collision>
      <origin rpy="1.5707963267948966 0 0" xyz="0 -0.08 0" />
      <geometry>
        <cylinder length="0.04" radius="0.046" />
      </geometry>
    </collision>
  </link>
  <joint
    name="RR_hip_joint"
    type="revolute">
    <origin
      xyz="-0.1934 -0.0465 0"
      rpy="0 0 0" />
    <parent
      link="base" />
    <child
      link="RR_hip" />
    <axis
      xyz="1 0 0" />
    <limit
      lower="-1.0472"
      upper="1.0472"
      effort="23.7"
      velocity="30.1" />
  </joint>
  <link name="RR_hip_rotor">
    <inertial>
      <origin rpy="0 0 0" xyz="0.0 0.0 0.0"/>
      <mass value="0.089"/>
      <inertia ixx="0.000111842" ixy="0.0" ixz="0.0" iyy="0.000059647" iyz="0.0" izz="0.000059647"/>
    </inertial>
  </link>
  <joint name="RR_hip_rotor_joint" type="fixed">
    <origin rpy="0 0 0" xyz="-0.11215 -0.04675 0"/>
    <parent link="base"/>
    <child link="RR_hip_rotor"/>
  </joint>
  <link
    name="RR_thigh">
    <inertial>
      <origin
        xyz="-0.00374 0.0223 -0.0327"
        rpy="0 0 0" />
      <mass
        value="1.152" />
      <inertia
        ixx="0.00584"
        ixy="-8.72E-05"
        ixz="-0.000289"
        iyy="0.0058"
        iyz="-0.000808"
        izz="0.00103" />
    </inertial>
    <visual>
      <origin
        xyz="0 0 0"
        rpy="0 0 0" />
      <geometry>
        <mesh
          filename="package://go2_description/dae/thigh_mirror.dae" />
      </geometry>
      <material
        name="">
        <color
          rgba="1 1 1 1" />
      </material>
    </visual>
    <collision>
      <origin rpy="0 1.5707963267948966 0" xyz="0 0 -0.1065" />
      <geometry>
        <box size="0.213 0.0245 0.034" />
      </geometry>
    </collision>
  </link>
  <joint
    name="RR_thigh_joint"
    type="revolute">
    <origin
      xyz="0 -0.0955 0"
      rpy="0 0 0" />
    <parent
      link="RR_hip" />
    <child
      link="RR_thigh" />
    <axis
      xyz="0 1 0" />
    <limit
      lower="-0.5236"
      upper="4.5379"
      effort="23.7"
      velocity="30.1" />
  </joint>
  <link name="RR_thigh_rotor">
    <inertial>
      <origin rpy="0 0 0" xyz="0.0 0.0 0.0"/>
      <mass value="0.089"/>
      <inertia ixx="0.000059647" ixy="0.0" ixz="0.0" iyy="0.000111842" iyz="0.0" izz="0.000059647"/>
    </inertial>
  </link>
  <joint name="RR_thigh_rotor_joint" type="fixed">
    <origin rpy="0 0 0" xyz="0 0.00015 0"/>
    <parent link="RR_hip"/>
    <child link="RR_thigh_rotor"/>
  </joint>
  <link
    name="RR_calf">
    <inertial>
      <origin
        xyz="0.00548 0.000975 -0.115"
        rpy="0 0 0" />
      <mass
        value="0.154" />
      <inertia
        ixx="0.00108"
        ixy="-3.4E-07"
        ixz="1.72E-05"
        iyy="0.0011"
        iyz="-8.28E-06"
        izz="3.29E-05" />
    </inertial>
    <visual>
      <origin
        xyz="0 0 0"
        rpy="0 0 0" />
      <geometry>
        <mesh
          filename="package://go2_description/dae/calf_mirror.dae" />
      </geometry>
      <material
        name="">
        <color
          rgba="1 1 1 1" />
      </material>
    </visual>
    <collision>
      <origin rpy="0 -0.2 0" xyz="0.01 0 -0.06" />
      <geometry>
        <cylinder length="0.12" radius="0.013" />
      </geometry>
    </collision>
  </link>
  <joint
    name="RR_calf_joint"
    type="revolute">
    <origin
      xyz="0 0 -0.213"
      rpy="0 0 0" />
    <parent
      link="RR_thigh" />
    <child
      link="RR_calf" />
    <axis
      xyz="0 1 0" />
    <limit
      lower="-2.7227"
      upper="-0.83776"
      effort="45.43"
      velocity="15.70" />
  </joint>
  <link
    name="RR_calflower">
    <collision>
      <origin rpy="0 0 0" xyz="0 0 0" />
      <geometry>
        <cylinder length="0.065" radius="0.011" />
      </geometry>
    </collision>
  </link>
  <joint
    name="RR_calflower_joint"
    type="fixed">
    <origin
      xyz="0.020 0 -0.148"
      rpy="0 0.05 0" />
    <parent
      link="RR_calf" />
    <child
      link="RR_calflower" />
    <axis
      xyz="0 0 0" />
  </joint>
  <link
    name="RR_calflower1">
    <collision>
      <origin rpy="0 0 0" xyz="0 0 0" />
      <geometry>
        <cylinder length="0.03" radius="0.0155" />
      </geometry>
    </collision>
  </link>
  <joint
    name="RR_calflower1_joint"
    type="fixed">
    <origin
      xyz="-0.01 0 -0.04"
      rpy="0 0.48 0" />
    <parent
      link="RR_calflower" />
    <child
      link="RR_calflower1" />
    <axis
      xyz="0 0 0" />
  </joint>
  <link name="RR_calf_rotor">
    <inertial>
      <origin rpy="0 0 0" xyz="0.0 0.0 0.0"/>
      <mass value="0.089"/>
      <inertia ixx="0.000059647" ixy="0.0" ixz="0.0" iyy="0.000111842" iyz="0.0" izz="0.000059647"/>
    </inertial>
  </link>
  <joint name="RR_calf_rotor_joint" type="fixed">
    <origin rpy="0 0 0" xyz="0 0.03235 0"/>
    <parent link="RR_thigh"/>
    <child link="RR_calf_rotor"/>
  </joint>
  <link
    name="RR_foot">
    <inertial>
      <origin
        xyz="0 0 0"
        rpy="0 0 0" />
      <mass
        value="0.04" />
      <inertia
        ixx="9.6e-06"
        ixy="0"
        ixz="0"
        iyy="9.6e-06"
        iyz="0"
        izz="9.6e-06" />
    </inertial>
    <visual>
      <origin
        xyz="0 0 0"
        rpy="0 0 0" />
      <geometry>
        <mesh
          filename="package://go2_description/dae/foot.dae" />
      </geometry>
      <material
        name="">
        <color
          rgba="1 1 1 1" />
      </material>
    </visual>
    <collision>
      <origin rpy="0 0 0" xyz="-0.002 0 0" />
      <geometry>
        <sphere radius="0.022" />
      </geometry>
    </collision>
  </link>
  <joint
    name="RR_foot_joint"
    type="fixed" dont_collapse="true">
    <origin
      xyz="0 0 -0.213"
      rpy="0 0 0" />
    <parent
      link="RR_calf" />
    <child
      link="RR_foot" />
    <axis
      xyz="0 0 0" />
  </joint>
  <link
    name="imu">
    <inertial>
      <origin
        xyz="0 0 0"
        rpy="0 0 0" />
      <mass
        value="0" />
      <inertia
        ixx="0"
        ixy="0"
        ixz="0"
        iyy="0"
        iyz="0"
        izz="0" />
    </inertial>
  </link>
  <joint
    name="imu_joint"
    type="fixed">
    <origin
      xyz="-0.02557 0 0.04232"
      rpy="0 0 0" />
    <parent
      link="base" />
    <child
      link="imu" />
    <axis
      xyz="0 0 0" />
  </joint>
  <link
    name="radar">
    <inertial>
      <origin
        xyz="0 0 0"
        rpy="0 0 0" />
      <mass
        value="0" />
      <inertia
        ixx="0"
        ixy="0"
        ixz="0"
        iyy="0"
        iyz="0"
        izz="0" />
    </inertial>
  </link>
  <joint
    name="radar_joint"
    type="fixed">
    <origin
      xyz="0.28945 0 -0.046825"
      rpy="0 2.8782 0" />
    <parent
      link="base" />
    <child
      link="radar" />
    <axis
      xyz="0 0 0" />
  </joint>



  <joint 
    name="front_camera_joint" 
    type="fixed">
    <origin 
      rpy="0 0 0" 
      xyz="0.32715 -0.00003 0.04297"/>
      <parent 
        link="base"/>
      <child 
      link="front_camera"/>
  </joint>
  <link name="front_camera">
        <visual>
        <origin xyz="0 0 0.0" rpy="0 0 0"/>
            <geometry>
                <box size="0.010 0.025 0.025"/>
            </geometry>
        <material name="black">
          <color rgba="0.0 0.0 0.0 1.0"/>
        </material>
        </visual>
        <collision>
        <origin xyz="0 0 0.0" rpy="0 0 0"/>
            <geometry>
                <box size="0.010 0.025 0.025"/>
            </geometry>
      <material name="black">
        <color rgba="0.0 0.0 0.0 1.0"/>
      </material>
        </collision>

  </link>

    <joint name="camera_optical_joint" type="fixed">
        <parent link="front_camera"/>
        <child link="camera_link_optical"/>
        <origin xyz="0 0 0" rpy="0 0 0"/>
    </joint>

    <link name="camera_link_optical">
      <material name="black">
        <color rgba="0.0 0.0 0.0 1.0"/>
      </material>
    <visual>
      <origin xyz="0 0 0" rpy="0 0 0"/>
      <geometry>
        <box size="0.01 0.01 0.01"/>  
      </geometry>
    </visual>

    <collision>
      <origin xyz="0 0 0" rpy="0 0 0"/>
      <geometry>
        <box size="0.01 0.01 0.01"/>  
      </geometry>
    </collision>

    </link>




<joint name="depth_camera_joint" type="fixed">
    <parent link="base"/>
    <child link="depth_camera_link"/>
    <origin xyz="0.3 -0.00003 0.08" rpy="0 0.3 0"/>
</joint>



<link name="depth_camera_link">
      <material name="black">
        <color rgba="0.0 0.0 0.0 1.0"/>
      </material>
    <visual>
        <geometry>
            <box size="0.015 0.08 0.025"/>  
        </geometry>
    </visual>
    <collision>
        <geometry>
            <box size="0.015 0.08 0.025"/>  
        </geometry>
    </collision>
</link>


<joint name="base_scan_joint" type="fixed">
    <parent link="Head_lower"/>
    <child link="base_scan"/>
    <origin xyz="0 0 0" rpy="0 0 0"/>
</joint>

<link name="base_scan">
      <material name="black">
        <color rgba="0.0 0.0 0.0 1.0"/>
      </material>
    <visual>
        <geometry>
            <box size="0.001 0.001 0.001"/>  
        </geometry>
    </visual>
    <collision>
        <geometry>
            <box size="0.001 0.001 0.001"/>  
        </geometry>
    </collision>
</link>

    <gazebo reference="front_camera">
        <material>Gazebo/Black</material>

        <sensor name="go2_camera" type="camera">
            <pose> 0 0 0 0 0 0 </pose>
            <visualize>true</visualize>
            <update_rate>10</update_rate>
            <camera>
                <camera_info_topic>go2_camera/camera_info</camera_info_topic>
                <horizontal_fov>1.089</horizontal_fov>
                <image>
                    <format>R8G8B8</format>
                    <width>640</width>
                    <height>480</height>
                </image>
                <clip>
                    <near>0.05</near>
                    <far>8.0</far>
                </clip>
                <noise>
                    <type>gaussian</type>
                    <mean>0.0</mean>
                    <stddev>0.007</stddev>
                </noise>
            </camera>
            <topic>go2_camera/image_raw</topic>
            <gz_frame_id>camera_link_optical</gz_frame_id>
        </sensor>
    </gazebo>


 <!-- <gazebo reference="depth_camera_link">
    <material>Gazebo/Black</material>
    
    <sensor name="go2_depth_camera" type="depth">
        <pose>0 0 0 0 0 0</pose>
        <visualize>true</visualize>
        <update_rate>10</update_rate>
        
        <camera>
            <depthImageTopicName>/go2_camera/depth/image_raw</depthImageTopicName>
            <depthImageCameraInfoTopicName>/go2_camera/depth/camera_info</depthImageCameraInfoTopicName>
            <pointCloudTopicName>/go2_camera/depth/points</pointCloudTopicName>
            
            <horizontal_fov>1.089</horizontal_fov>
            <image>
                <format>R8G8B8</format>
                <width>640</width>
                <height>480</height>
            </image>
            <clip>
                <near>0.05</near>
                <far>8.0</far>
            </clip>
            <noise>
                <type>gaussian</type>
                <mean>0.0</mean>
                <stddev>0.007</stddev>
            </noise>
        </camera> -->

        <!-- <topic>/go2_camera/depth/image_raw</topic>
        <frameName>depth_camera_link</frameName>
        <pointCloudCutoff>0.5</pointCloudCutoff>
        <pointCloudCutoffMax>3.0</pointCloudCutoffMax> -->


      <!-- <plugin
        name="ignition_ros2_depth_camera"
        filename="ignition-gazebo-depth-camera-system">
        <ros>
          <namespace>depth_camera</namespace>
          <topic>/go2_camera/depth/image_raw</topic>
        </ros>
      </plugin> -->

<!-- <plugin name="ignition::gazebo::systems::DepthCamera" filename="ignition-gazebo-depth-camera-system"> -->
  <!-- <topic>/go2/depth_camera/points</topic> 
  <image_topic>/go2/depth_camera/image_raw</image_topic> 
  <camera_info_topic>/go2/depth_camera/camera_info</camera_info_topic> -->
<!-- </plugin> -->



    <!-- </sensor>
</gazebo> -->




<gazebo reference="depth_camera_link">
    <material>Gazebo/Black</material>
    
    <sensor name="go2_depth_camera" type="depth">
        <pose>0 0 0 0 0 0</pose>
        <visualize>true</visualize>
        <update_rate>10</update_rate>
        
        <camera>
            <depthImageTopicName>/go2_camera/depth/image_raw</depthImageTopicName>
            <depthImageCameraInfoTopicName>/go2_camera/depth/camera_info</depthImageCameraInfoTopicName>
            <pointCloudTopicName>/go2_camera/depth/points</pointCloudTopicName>
            
            <horizontal_fov>1.089</horizontal_fov>
            <image>
                <format>R8G8B8</format>
                <width>640</width>
                <height>480</height>
            </image>
            <clip>
                <near>0.05</near>
                <far>8.0</far>
            </clip>
            <noise>
                <type>gaussian</type>
                <mean>0.0</mean>
                <stddev>0.007</stddev>
            </noise>
        </camera>
    </sensor>
</gazebo>




    <!-- <gazebo reference="depth_camera_link">
        <material>Gazebo/Black</material>
        <sensor name="camera" type="depth">
            <pose> 0 0 0 0 0 0 </pose>
            <visualize>true</visualize>
            <update_rate>10</update_rate>
            <camera>
                <horizontal_fov>1.089</horizontal_fov>
                <image>
                    <format>B8G8R8</format>
                    <width>640</width>
                    <height>480</height>
                </image>
                <clip>
                    <near>0.05</near>
                    <far>8.0</far>
                </clip>
            </camera>
            <frame_name>camera_link_optical</frame_name>
            <min_depth>0.1</min_depth>
            <max_depth>100.0</max_depth>
        </sensor>
    </gazebo> -->



<gazebo reference="base_scan" >
  <selfCollide>false</selfCollide>
    <material>Gazebo/Black</material>
    <mu1 value="0.05" />
    <mu2 value="0.05" />
  <sensor name="base_scan" type="gpu_lidar">
    <gz_frame_id>base_scan</gz_frame_id>
    <topic>go2/scan</topic>
    <update_rate>30</update_rate>
    <lidar>
      <scan>
        <horizontal>
          <samples>2800</samples>
          <resolution>1</resolution>
          <min_angle>-3.14</min_angle>
          <max_angle>3.14</max_angle>
        </horizontal>
        <vertical>
          <samples>1</samples>
          <resolution>0.1</resolution>
          <min_angle>0.0</min_angle>
          <max_angle>0.0</max_angle>
        </vertical>
      </scan>
      <range>
        <min>0.2</min>
        <max>30.0</max>
        <resolution>0.01</resolution>
      </range>
      <frame_id>/base_scan</frame_id>
      </lidar>
    <alwaysOn>true</alwaysOn>
    <visualize>true</visualize>
  </sensor>
</gazebo>

   <gazebo>

      <plugin filename="ignition-gazebo-sensors-system" name="ignition::gazebo::systems::Sensors">
        <render_engine>ogre2</render_engine>
      </plugin>

    </gazebo>




</robot>